Workbook

Sheet Task
C3: Sr No | D3: Task
C4: 1 | D4: Get the Cross-Sold GWP for Liability products and which is the highest Cross-Sold Product?
C5: 2 | D5: Create a dashboard to analyse POS Data with KPIs and gather insights on the same
C6: 3 | D6: Map policy category to the policy type using data from appendix
C8: Average commission to consider
C9: Product | E9: %
C10: Liability - Non POS | E10: 0.2
C11: P&C - Non POS | E11: 0.2
C12: Others -Non POS | E12: 0.15
C13: Policies booked through POS GTM | E13: 0.05 | F13: -> Retained by BK

Sheet Liability_client

Sheet Cross Sold GWP
A2: Client Id | B2: COUNTA of Policy Name | C2: SUM of Gross Premium
A3: 1 | B3: 4 | C3: 8358500
A4: 4 | B4: 1 | C4: 2714000
A5: 6 | B5: 19 | C5: 17967556
A6: 8 | B6: 2 | C6: 3948062
A7: 10 | B7: 2 | C7: 2047600
A8: 11 | B8: 1 | C8: 908400
A9: 12 | B9: 1 | C9: 8850000
A10: 15 | B10: 67 | C10: 325250630
A11: 16 | B11: 1 | C11: 3717000
A12: 17 | B12: 3 | C12: 1323558
A13: 18 | B13: 3 | C13: 2706980
A14: 20 | B14: 3 | C14: 301562
... A3376: 3619 | B3376: 1 | C3376: 3540000
A3377: (blank)

Sheet Raw Data
A1: PL NO | B1: Client Id | C1: Sales Channel | D1: POS Location | E1: Insurer Name | F1: Category | G1: Policy Name | H1: Policy Start Date | I1: Policy End Date | J1: Gross Premium | K1: Total GST Amount | L1: Net Premium | M1: Total Brokerage Received | N1: Client Type | O1: Policy MIS New | P1: Type of Purchase (New Client/Old Client) | Q1: HasLiability | R1: IsCrossSold
A2: PL 158 | B2: 67 | C2: Ads | D2: Not POS | E2: Future Generali India Insurance Co Ltd | F2: =VLOOKUP(G2,'Policy Type'!$A:$B,2,FALSE) -> Liability | G2: Workmen Compensation | H2: 45139 | I2: 45504 | J2: 6200800 | K2: =J2*0.18 -> 1116144 | L2: =J2+K2 -> 7316944 | M2: =L2*0.2 -> 1463388.8 | N2: Corporate | O2: Rollover | P2: =IF(COUNTIF(B:B,B2)=1,"New Client","Old Client") -> Old Client | Q2: =IF(COUNTIFS($B:$B,$B2,$F:$F,"Liability")>0,"Yes","No") -> Yes | R2: =IF(AND($Q2="Yes",$F2<>"Liability"),"Cross-Sold","")
A3: PL 252 | B3: 70 | C3: BD | D3: Not POS | E3: Bajaj Allianz General Insurance Co Ltd | F3: =VLOOKUP(G3,'Policy Type'!$A:$B,2,FALSE) -> P&C | G3: Burglary | H3: 45139 | I3: 45504 | J3: 550000 | K3: =J3*0.18 -> 99000 | L3: =J3+K3 -> 649000 | M3: =L3*0.2 -> 129800 | N3: Corporate | O3: Rollover | P3: =IF(COUNTIF(B:B,B3)=1,"New Client","Old Client") -> Old Client | Q3: =IF(COUNTIFS($B:$B,$B3,$F:$F,"Liability")>0,"Yes","No") -> Yes | R3: =IF(AND($Q3="Yes",$F3<>"Liability"),"Cross-Sold","") -> Cross-Sold
A4: PL 324 | B4: 122 | C4: POS | D4: Nagpur | E4: Bajaj Allianz General Insurance Co Ltd | F4: =VLOOKUP(G4,'Policy Type'!$A:$B,2,FALSE) -> P&C | G4: Marine Open | H4: 45139 | I4: 45504 | J4: 4130100 | K4: =J4*0.18 -> 743418 | L4: =J4+K4 -> 4873518 | M4: =L4*0.05 -> 243675.9 | N4: Corporate | O4: New | P4: =IF(COUNTIF(B:B,B4)=1,"New Client","Old Client") -> Old Client | Q4: =IF(COUNTIFS($B:$B,$B4,$F:$F,"Liability")>0,"Yes","No") -> Yes | R4: =IF(AND($Q4="Yes",$F4<>"Liability"),"Cross-Sold","") -> Cross-Sold
A5: PL 382 | B5: 146 | C5: BD | D5: Not POS | E5: Bajaj Allianz General Insurance Co Ltd | F5: =VLOOKUP(G5,'Policy Type'!$A:$B,2,FALSE) -> P&C | G5: Premium Personal Guard | H5: 45150 | I5: 45515 | J5: 153400 | K5: =J5*0.18 -> 27612 | L5: =J5+K5 -> 181012 | M5: =L5*0.2 -> 36202.4 | N5: Retail | O5: Renew | P5: =IF(COUNTIF(B:B,B5)=1,"New Client","Old Client") -> New Client | Q5: =IF(COUNTIFS($B:$B,$B5,$F:$F,"Liability")>0,"Yes","No") -> No | R5: =IF(AND($Q5="Yes",$F5<>"Liability"),"Cross-Sold","")
A6: PL 390 | B6: 149 | C6: Ads | D6: Not POS | E6: Bajaj Allianz General Insurance Co Ltd | F6: =VLOOKUP(G6,'Policy Type'!$A:$B,2,FALSE) -> P&C | G6: Two Wheeler | H6: 45139 | I6: 45504 | J6: 141128 | K6: =J6*0.18 -> 25403.04 | L6: =J6+K6 -> 166531.04 | M6: =L6*0.2 -> 33306.208 | N6: Retail | O6: Renew | P6: =IF(COUNTIF(B:B,B6)=1,"New Client","Old Client") -> New Client | Q6: =IF(COUNTIFS($B:$B,$B6,$F:$F,"Liability")>0,"Yes","No") -> No | R6: =IF(AND($Q6="Yes",$F6<>"Liability"),"Cross-Sold","")
A7: PL 404 | B7: 153 | C7: Offline | D7: Not POS | E7: Bajaj Allianz General Insurance Co Ltd | F7: =VLOOKUP(G7,'Policy Type'!$A:$B,2,FALSE) -> Liability | G7: D & O | H7: 45139 | I7: 45504 | J7: 2124000 | K7: =J7*0.18 -> 382320 | L7: =J7+K7 -> 2506320 | M7: =L7*0.2 -> 501264 | N7: Corporate | O7: Renew | P7: =IF(COUNTIF(B:B,B7)=1,"New Client","Old Client") -> New Client | Q7: =IF(COUNTIFS($B:$B,$B7,$F:$F,"Liability")>0,"Yes","No") -> Yes | R7: =IF(AND($Q7="Yes",$F7<>"Liability"),"Cross-Sold","")
A8: PL 437 | B8: 165 | C8: Offline | D8: Not POS | E8: United India Insurance Co Ltd | F8: =VLOOKUP(G8,'Policy Type'!$A:$B,2,FALSE) -> P&C | G8: Two Wheeler | H8: 45139 | I8: 45504 | J8: 286740 | K8: =J8*0.18 -> 51613.2 | L8: =J8+K8 -> 338353.2 | M8: =L8*0.2 -> 67670.64 | N8: Retail | O8: Renew | P8: =IF(COUNTIF(B:B,B8)=1,"New Client","Old Client") -> Old Client | Q8: =IF(COUNTIFS($B:$B,$B8,$F:$F,"Liability")>0,"Yes","No") -> Yes | R8: =IF(AND($Q8="Yes",$F8<>"Liability"),"Cross-Sold","") -> Cross-Sold
A9: PL 449 | B9: 171 | C9: Ads | D9: Not POS | E9: United India Insurance Co Ltd | F9: =VLOOKUP(G9,'Policy Type'!$A:$B,2,FALSE) -> P&C | G9: Two wheeler - TP | H9: 45143 | I9: 45508 | J9: 116700 | K9: =J9*0.18 -> 21006 | L9: =J9+K9 -> 137706 | M9: =L9*0.2 -> 27541.2 | N9: Retail | O9: Rollover | P9: =IF(COUNTIF(B:B,B9)=1,"New Client","Old Client") -> New Client | Q9: =IF(COUNTIFS($B:$B,$B9,$F:$F,"Liability")>0,"Yes","No") -> No | R9: =IF(AND($Q9="Yes",$F9<>"Liability"),"Cross-Sold","")
A10: PL 481 | B10: 182 | C10: Offline | D10: Not POS | E10: Future Generali India Insurance Co Ltd | F10: =VLOOKUP(G10,'Policy Type'!$A:$B,2,FALSE) -> P&C | G10: Two Wheeler | H10: 45139 | I10: 45504 | J10: 118472 | K10: =J10*0.18 -> 21324.96 | L10: =J10+K10 -> 139796.96 | M10: =L10*0.2 -> 27959.392 | N10: Corporate | O10: Renew | P10: =IF(COUNTIF(B:B,B10)=1,"New Client","Old Client") -> Old Client | Q10: =IF(COUNTIFS($B:$B,$B10,$F:$F,"Liability")>0,"Yes","No") -> No | R10: =IF(AND($Q10="Yes",$F10<>"Liability"),"Cross-Sold","")
A11: PL 511 | B11: 170 | C11: Ads | D11: Not POS | E11: Bajaj Allianz General Insurance Co Ltd | F11: =VLOOKUP(G11,'Policy Type'!$A:$B,2,FALSE) -> P&C | G11: Two Wheeler | H11: 45161 | I11: 45526 | J11: 148798 | K11: =J11*0.18 -> 26783.64 | L11: =J11+K11 -> 175581.64 | M11: =L11*0.2 -> 35116.328 | N11: Retail | O11: Renew | P11: =IF(COUNTIF(B:B,B11)=1,"New Client","Old Client") -> Old Client | Q11: =IF(COUNTIFS($B:$B,$B11,$F:$F,"Liability")>0,"Yes","No") -> Yes | R11: =IF(AND($Q11="Yes",$F11<>"Liability"),"Cross-Sold","") -> Cross-Sold
A12: PL 513 | B12: 188 | C12: POS | D12: Ahemdabad | E12: Bajaj Allianz General Insurance Co Ltd | F12: =VLOOKUP(G12,'Policy Type'!$A:$B,2,FALSE) -> P&C | G12: Two Wheeler | H12: 45142 | I12: 45507 | J12: 141954 | K12: =J12*0.18 -> 25551.72 | L12: =J12+K12 -> 167505.72 | M12: =L12*0.05 -> 8375.286 | N12: Retail | O12: Renew | P12: =IF(COUNTIF(B:B,B12)=1,"New Client","Old Client") -> Old Client | Q12: =IF(COUNTIFS($B:$B,$B12,$F:$F,"Liability")>0,"Yes","No") -> Yes | R12: =IF(AND($Q12="Yes",$F12<>"Liability"),"Cross-Sold","") -> Cross-Sold
A13: PL 515 | B13: 189 | C13: POS | D13: Ahemdabad | E13: Bajaj Allianz General Insurance Co Ltd | F13: =VLOOKUP(G13,'Policy Type'!$A:$B,2,FALSE) -> P&C | G13: Private Car | H13: 45140 | I13: 45505 | J13: 651800 | K13: =J13*0.18 -> 117324 | L13: =J13+K13 -> 769124 | M13: =L13*0.05 -> 38456.2 | N13: Corporate | O13: Renew | P13: =IF(COUNTIF(B:B,B13)=1,"New Client","Old Client") -> Old Client | Q13: =IF(COUNTIFS($B:$B,$B13,$F:$F,"Liability")>0,"Yes","No") -> No | R13: =IF(AND($Q13="Yes",$F13<>"Liability"),"Cross-Sold","")
A14: PL 517 | B14: 190 | C14: Offline | D14: Not POS | E14: Bajaj Allianz General Insurance Co Ltd | F14: =VLOOKUP(G14,'Policy Type'!$A:$B,2,FALSE) -> P&C | G14: Private Car | H14: 45169 | I14: 45534 | J14: 768298 | K14: =J14*0.18 -> 138293.64 | L14: =J14+K14 -> 906591.64 | M14: =L14*0.2 -> 181318.33 | N14: Retail | O14: Renew | P14: =IF(COUNTIF(B:B,B14)=1,"New Client","Old Client") -> New Client | Q14: =IF(COUNTIFS($B:$B,$B14,$F:$F,"Liability")>0,"Yes","No") -> No | R14: =IF(AND($Q14="Yes",$F14<>"Liability"),"Cross-Sold","")
A15: PL 522 | B15: 193 | C15: BD | D15: Not POS | E15: Bajaj Allianz General Insurance Co Ltd | F15: =VLOOKUP(G15,'Policy Type'!$A:$B,2,FALSE) -> P&C | G15: Two Wheeler | H15: 45141 | I15: 45506 | J15: 161306 | K15: =J15*0.18 -> 29035.08 | L15: =J15+K15 -> 190341.08 | M15: =L15*0.2 -> 38068.216 | N15: Retail | O15: Rollover | P15: =IF(COUNTIF(B:B,B15)=1,"New Client","Old Client") -> Old Client | Q15: =IF(COUNTIFS($B:$B,$B15,$F:$F,"Liability")>0,"Yes","No") -> No | R15: =IF(AND($Q15="Yes",$F15<>"Liability"),"Cross-Sold","")
A16: PL 524 | B16: 191 | C16: BD | D16: Not POS | E16: Bajaj Allianz General Insurance Co Ltd | F16: =VLOOKUP(G16,'Policy Type'!$A:$B,2,FALSE) -> P&C | G16: Two Wheeler - OD | H16: 45141 | I16: 45506 | J16: 109100 | K16: =J16*0.18 -> 19638 | L16: =J16+K16 -> 128738 | M16: =L16*0.2 -> 25747.6 | N16: Retail | O16: Rollover | P16: =IF(COUNTIF(B:B,B16)=1,"New Client","Old Client") -> New Client | Q16: =IF(COUNTIFS($B:$B,$B16,$F:$F,"Liability")>0,"Yes","No") -> No | R16: =IF(AND($Q16="Yes",$F16<>"Liability"),"Cross-Sold","")
A17: PL 526 | B17: 121 | C17: Ads | D17: Not POS | E17: Bajaj Allianz General Insurance Co Ltd | F17: =VLOOKUP(G17,'Policy Type'!$A:$B,2,FALSE) -> P&C | G17: Private Car | H17: 45144 | I17: 45509 | J17: 2905396 | K17: =J17*0.18 -> 522971.28 | L17: =J17+K17 -> 3428367.3 | M17: =L17*0.2 -> 685673.46 | N17: Retail | O17: Rollover | P17: =IF(COUNTIF(B:B,B17)=1,"New Client","Old Client") -> New Client | Q17: =IF(COUNTIFS($B:$B,$B17,$F:$F,"Liability")>0,"Yes","No") -> No | R17: =IF(AND($Q17="Yes",$F17<>"Liability"),"Cross-Sold","")
A18: PL 528 | B18: 194 | C18: Offline | D18: Not POS | E18: Bajaj Allianz General Insurance Co Ltd | F18: =VLOOKUP(G18,'Policy Type'!$A:$B,2,FALSE) -> P&C | G18: Two Wheeler - OD | H18: 45148 | I18: 45513 | J18: 92200 | K18: =J18*0.18 -> 16596 | L18: =J18+K18 -> 108796 | M18: =L18*0.2 -> 21759.2 | N18: Retail | O18: Rollover | P18: =IF(COUNTIF(B:B,B18)=1,"New Client","Old Client") -> Old Client | Q18: =IF(COUNTIFS($B:$B,$B18,$F:$F,"Liability")>0,"Yes","No") -> No | R18: =IF(AND($Q18="Yes",$F18<>"Liability"),"Cross-Sold","")
A19: PL 530 | B19: 195 | C19: POS | D19: Mumbai | E19: Bajaj Allianz General Insurance Co Ltd | F19: =VLOOKUP(G19,'Policy Type'!$A:$B,2,FALSE) -> P&C | G19: Private Car | H19: 45152 | I19: 45517 | J19: 698324 | K19: =J19*0.18 -> 125698.32 | L19: =J19+K19 -> 824022.32 | M19: =L19*0.05 -> 41201.116 | N19: Retail | O19: Rollover | P19: =IF(COUNTIF(B:B,B19)=1,"New Client","Old Client") -> New Client | Q19: =IF(COUNTIFS($B:$B,$B19,$F:$F,"Liability")>0,"Yes","No") -> No | R19: =IF(AND($Q19="Yes",$F19<>"Liability"),"Cross-Sold","")
A20: PL 532 | B20: 196 | C20: Offline | D20: Not POS | E20: ICICI Lombard General Insurance Co Ltd | F20: =VLOOKUP(G20,'Policy Type'!$A:$B,2,FALSE) -> P&C | G20: Private Car | H20: 45149 | I20: 45514 | J20: 1326556 | K20: =J20*0.18 -> 238780.08 | L20: =J20+K20 -> 1565336.1 | M20: =L20*0.2 -> 313067.22 | N20: Retail | O20: Rollover | P20: =IF(COUNTIF(B:B,B20)=1,"New Client","Old Client") -> New Client | Q20: =IF(COUNTIFS($B:$B,$B20,$F:$F,"Liability")>0,"Yes","No") -> No | R20: =IF(AND($Q20="Yes",$F20<>"Liability"),"Cross-Sold","")
A21: PL 534 | B21: 107 | C21: POS | D21: Nagpur | E21: Future Generali India Insurance Co Ltd | F21: =VLOOKUP(G21,'Policy Type'!$A:$B,2,FALSE) -> P&C | G21: Specific Marine | H21: 45139 | I21: 45139 | J21: 106300 | K21: =J21*0.18 -> 19134 | L21: =J21+K21 -> 125434 | M21: =L21*0.05 -> 6271.7 | N21: Corporate | O21: New | P21: =IF(COUNTIF(B:B,B21)=1,"New Client","Old Client") -> Old Client | Q21: =IF(COUNTIFS($B:$B,$B21,$F:$F,"Liability")>0,"Yes","No") -> No | R21: =IF(AND($Q21="Yes",$F21<>"Liability"),"Cross-Sold","")
A22: PL 536 | B22: 70 | C22: Offline | D22: Not POS | E22: ICICI Lombard General Insurance Co Ltd | F22: =VLOOKUP(G22,'Policy Type'!$A:$B,2,FALSE) -> P&C | G22: Marine Open | H22: 45139 | I22: 45504 | J22: 11800100 | K22: =J22*0.18 -> 2124018 | L22: =J22+K22 -> 13924118 | M22: =L22*0.2 -> 2784823.6 | N22: Corporate | O22: New | P22: =IF(COUNTIF(B:B,B22)=1,"New Client","Old Client") -> Old Client | Q22: =IF(COUNTIFS($B:$B,$B22,$F:$F,"Liability")>0,"Yes","No") -> Yes | R22: =IF(AND($Q22="Yes",$F22<>"Liability"),"Cross-Sold","") -> Cross-Sold
A23: PL 538 | B23: 197 | C23: Ads | D23: Not POS | E23: Future Generali India Insurance Co Ltd | F23: =VLOOKUP(G23,'Policy Type'!$A:$B,2,FALSE) -> P&C | G23: Specific Marine | H23: 45140 | I23: 45140 | J23: 604500 | K23: =J23*0.18 -> 108810 | L23: =J23+K23 -> 713310 | M23: =L23*0.2 -> 142662 | N23: Corporate | O23: New | P23: =IF(COUNTIF(B:B,B23)=1,"New Client","Old Client") -> Old Client | Q23: =IF(COUNTIFS($B:$B,$B23,$F:$F,"Liability")>0,"Yes","No") -> Yes | R23: =IF(AND($Q23="Yes",$F23<>"Liability"),"Cross-Sold","") -> Cross-Sold
A24: PL 540 | B24: 198 | C24: Offline | D24: Not POS | E24: HDFC Ergo General Insurance Co Ltd | F24: =VLOOKUP(G24,'Policy Type'!$A:$B,2,FALSE) -> Liability | G24: D & O | H24: 45157 | I24: 45522 | J24: 1770000 | K24: =J24*0.18 -> 318600 | L24: =J24+K24 -> 2088600 | M24: =L24*0.2 -> 417720 | N24: Corporate | O24: Rollover | P24: =IF(COUNTIF(B:B,B24)=1,"New Client","Old Client") -> Old Client | Q24: =IF(COUNTIFS($B:$B,$B24,$F:$F,"Liability")>0,"Yes","No") -> Yes | R24: =IF(AND($Q24="Yes",$F24<>"Liability"),"Cross-Sold","")
A25: PL 541 | B25: 198 | C25: BD | D25: Not POS | E25: HDFC Ergo General Insurance Co Ltd | F25: =VLOOKUP(G25,'Policy Type'!$A:$B,2,FALSE) -> Liability | G25: E & O | H25: 45157 | I25: 45522 | J25: 4720000 | K25: =J25*0.18 -> 849600 | L25: =J25+K25 -> 5569600 | M25: =L25*0.2 -> 1113920 | N25: Corporate | O25: Rollover | P25: =IF(COUNTIF(B:B,B25)=1,"New Client","Old Client") -> Old Client | Q25: =IF(COUNTIFS($B:$B,$B25,$F:$F,"Liability")>0,"Yes","No") -> Yes | R25: =IF(AND($Q25="Yes",$F25<>"Liability"),"Cross-Sold","")
A26: PL 542 | B26: 199 | C26: POS | D26: Indore | E26: Bajaj Allianz General Insurance Co Ltd | F26: =VLOOKUP(G26,'Policy Type'!$A:$B,2,FALSE) -> P&C | G26: Star Package | H26: 45167 | I26: 45532 | J26: 1965400 | K26: =J26*0.18 -> 353772 | L26: =J26+K26 -> 2319172 | M26: =L26*0.05 -> 115958.6 | N26: Retail | O26: Rollover | P26: =IF(COUNTIF(B:B,B26)=1,"New Client","Old Client") -> Old Client | Q26: =IF(COUNTIFS($B:$B,$B26,$F:$F,"Liability")>0,"Yes","No") -> Yes | R26: =IF(AND($Q26="Yes",$F26<>"Liability"),"Cross-Sold","") -> Cross-Sold
A27: PL 543 | B27: 117 | C27: Ads | D27: Not POS | E27: Cholamandalam MS General Insurance | F27: =VLOOKUP(G27,'Policy Type'!$A:$B,2,FALSE) -> P&C | G27: Shopkeeper | H27: 45140 | I27: 45505 | J27: 2245000 | K27: =J27*0.18 -> 404100 | L27: =J27+K27 -> 2649100 | M27: =L27*0.2 -> 529820 | N27: Corporate | O27: New | P27: =IF(COUNTIF(B:B,B27)=1,"New Client","Old Client") -> Old Client | Q27: =IF(COUNTIFS($B:$B,$B27,$F:$F,"Liability")>0,"Yes","No") -> Yes | R27: =IF(AND($Q27="Yes",$F27<>"Liability"),"Cross-Sold","") -> Cross-Sold
A28: PL 545 | B28: 200 | C28: BD | D28: Not POS | E28: HDFC Ergo General Insurance Co Ltd | F28: =VLOOKUP(G28,'Policy Type'!$A:$B,2,FALSE) -> Liability | G28: Public Liability | H28: 45140 | I28: 45505 | J28: 1062000 | K28: =J28*0.18 -> 191160 | L28: =J28+K28 -> 1253160 | M28: =L28*0.2 -> 250632 | N28: Corporate | O28: New | P28: =IF(COUNTIF(B:B,B28)=1,"New Client","Old Client") -> Old Client | Q28: =IF(COUNTIFS($B:$B,$B28,$F:$F,"Liability")>0,"Yes","No") -> Yes | R28: =IF(AND($Q28="Yes",$F28<>"Liability"),"Cross-Sold","")
A29: PL 546 | B29: 201 | C29: POS | D29: Ahemdabad | E29: Future Generali India Insurance Co Ltd | F29: =VLOOKUP(G29,'Policy Type'!$A:$B,2,FALSE) -> P&C | G29: Specific Marine | H29: 45140 | I29: 45140 | J29: 115000 | K29: =J29*0.18 -> 20700 | L29: =J29+K29 -> 135700 | M29: =L29*0.05 -> 6785 | N29: Corporate | O29: New | P29: =IF(COUNTIF(B:B,B29)=1,"New Client","Old Client") -> Old Client | Q29: =IF(COUNTIFS($B:$B,$B29,$F:$F,"Liability")>0,"Yes","No") -> No | R29: =IF(AND($Q29="Yes",$F29<>"Liability"),"Cross-Sold","")
A30: PL 547 | B30: 202 | C30: Offline | D30: Not POS | E30: Cholamandalam MS General Insurance | F30: =VLOOKUP(G30,'Policy Type'!$A:$B,2,FALSE) -> Liability | G30: Workmen Compensation | H30: 45141 | I30: 45506 | J30: 336400 | K30: =J30*0.18 -> 60552 | L30: =J30+K30 -> 396952 | M30: =L30*0.2 -> 79390.4 | N30: Corporate | O30: New | P30: =IF(COUNTIF(B:B,B30)=1,"New Client","Old Client") -> Old Client | Q30: =IF(COUNTIFS($B:$B,$B30,$F:$F,"Liability")>0,"Yes","No") -> Yes | R30: =IF(AND($Q30="Yes",$F30<>"Liability"),"Cross-Sold","")
A31: PL 548 | B31: 200 | C31: Offline | D31: Not POS | E31: HDFC Ergo General Insurance Co Ltd | F31: =VLOOKUP(G31,'Policy Type'!$A:$B,2,FALSE) -> P&C | G31: Bharat Sookshma Udyam Suraksha | H31: 45141 | I31: 45506 | J31: 1301500 | K31: =J31*0.18 -> 234270 | L31: =J31+K31 -> 1535770 | M31: =L31*0.2 -> 307154 | N31: Corporate | O31: New | P31: =IF(COUNTIF(B:B,B31)=1,"New Client","Old Client") -> Old Client | Q31: =IF(COUNTIFS($B:$B,$B31,$F:$F,"Liability")>0,"Yes","No") -> Yes | R31: =IF(AND($Q31="Yes",$F31<>"Liability"),"Cross-Sold","") -> Cross-Sold
A32: PL 549 | B32: 203 | C32: POS | D32: Mumbai | E32: HDFC Ergo General Insurance Co Ltd | F32: =VLOOKUP(G32,'Policy Type'!$A:$B,2,FALSE) -> Liability | G32: D & O | H32: 45141 | I32: 45506 | J32: 1062000 | K32: =J32*0.18 -> 191160 | L32: =J32+K32 -> 1253160 | M32: =L32*0.05 -> 62658 | N32: Corporate | O32: New | P32: =IF(COUNTIF(B:B,B32)=1,"New Client","Old Client") -> Old Client | Q32: =IF(COUNTIFS($B:$B,$B32,$F:$F,"Liability")>0,"Yes","No") -> Yes | R32: =IF(AND($Q32="Yes",$F32<>"Liability"),"Cross-Sold","")
A33: PL 550 | B33: 203 | C33: Offline | D33: Not POS | E33: HDFC Ergo General Insurance Co Ltd | F33: =VLOOKUP(G33,'Policy Type'!$A:$B,2,FALSE) -> Liability | G33: Commercial General Liability | H33: 45141 | I33: 45506 | J33: 826000 | K33: =J33*0.18 -> 148680 | L33: =J33+K33 -> 974680 | M33: =L33*0.2 -> 194936 | N33: Corporate | O33: New | P33: =IF(COUNTIF(B:B,B33)=1,"New Client","Old Client") -> Old Client | Q33: =IF(COUNTIFS($B:$B,$B33,$F:$F,"Liability")>0,"Yes","No") -> Yes | R33: =IF(AND($Q33="Yes",$F33<>"Liability"),"Cross-Sold","")
A34: PL 551 | B34: 204 | C34: Offline | D34: Not POS | E34: New India Assurance company | F34: =VLOOKUP(G34,'Policy Type'!$A:$B,2,FALSE) -> P&C | G34: Bharat Sookshma Udyam Suraksha | H34: 45142 | I34: 45507 | J34: 4864000 | K34: =J34*0.18 -> 875520 | L34: =J34+K34 -> 5739520 | M34: =L34*0.2 -> 1147904 | N34: Corporate | O34: New | P34: =IF(COUNTIF(B:B,B34)=1,"New Client","Old Client") -> New Client | Q34: =IF(COUNTIFS($B:$B,$B34,$F:$F,"Liability")>0,"Yes","No") -> No | R34: =IF(AND($Q34="Yes",$F34<>"Liability"),"Cross-Sold","")
A35: PL 552 | B35: 116 | C35: POS | D35: Indore | E35: ICICI Lombard General Insurance Co Ltd | F35: =VLOOKUP(G35,'Policy Type'!$A:$B,2,FALSE) -> Liability | G35: Cyber Crime | H35: 45141 | I35: 45506 | J35: 42477100 | K35: =J35*0.18 -> 7645878 | L35: =J35+K35 -> 50122978 | M35: =L35*0.05 -> 2506148.9 | N35: Corporate | O35: New | P35: =IF(COUNTIF(B:B,B35)=1,"New Client","Old Client") -> Old Client | Q35: =IF(COUNTIFS($B:$B,$B35,$F:$F,"Liability")>0,"Yes","No") -> Yes | R35: =IF(AND($Q35="Yes",$F35<>"Liability"),"Cross-Sold","")
A36: PL 553 | B36: 15 | C36: Ads | D36: Not POS | E36: Future Generali India Insurance Co Ltd | F36: =VLOOKUP(G36,'Policy Type'!$A:$B,2,FALSE) -> P&C | G36: Specific Marine | H36: 45143 | I36: 45143 | J36: 212900 | K36: =J36*0.18 -> 38322 | L36: =J36+K36 -> 251222 | M36: =L36*0.2 -> 50244.4 | N36: Corporate | O36: New | P36: =IF(COUNTIF(B:B,B36)=1,"New Client","Old Client") -> Old Client | Q36: =IF(COUNTIFS($B:$B,$B36,$F:$F,"Liability")>0,"Yes","No") -> Yes | R36: =IF(AND($Q36="Yes",$F36<>"Liability"),"Cross-Sold","") -> Cross-Sold
A37: PL 554 | B37: 205 | C37: Offline | D37: Not POS | E37: SBI General Insurance Co Ltd | F37: =VLOOKUP(G37,'Policy Type'!$A:$B,2,FALSE) -> Liability | G37: Public Liability | H37: 45145 | I37: 45510 | J37: 295000 | K37: =J37*0.18 -> 53100 | L37: =J37+K37 -> 348100 | M37: =L37*0.2 -> 69620 | N37: Corporate | O37: New | P37: =IF(COUNTIF(B:B,B37)=1,"New Client","Old Client") -> New Client | Q37: =IF(COUNTIFS($B:$B,$B37,$F:$F,"Liability")>0,"Yes","No") -> Yes | R37: =IF(AND($Q37="Yes",$F37<>"Liability"),"Cross-Sold","")
A38: PL 555 | B38: 206 | C38: BD | D38: Not POS | E38: Future Generali India Insurance Co Ltd | F38: =VLOOKUP(G38,'Policy Type'!$A:$B,2,FALSE) -> P&C | G38: Specific Marine | H38: 45145 | I38: 45145 | J38: 67300 | K38: =J38*0.18 -> 12114 | L38: =J38+K38 -> 79414 | M38: =L38*0.2 -> 15882.8 | N38: Corporate | O38: New | P38: =IF(COUNTIF(B:B,B38)=1,"New Client","Old Client") -> Old Client | Q38: =IF(COUNTIFS($B:$B,$B38,$F:$F,"Liability")>0,"Yes","No") -> No | R38: =IF(AND($Q38="Yes",$F38<>"Liability"),"Cross-Sold","")
A39: PL 556 | B39: 207 | C39: POS | D39: Mumbai | E39: Bajaj Allianz General Insurance Co Ltd | F39: =VLOOKUP(G39,'Policy Type'!$A:$B,2,FALSE) -> Others | G39: Travel | H39: 45172 | I39: 45231 | J39: 250600 | K39: =J39*0.18 -> 45108 | L39: =J39+K39 -> 295708 | M39: =L39*0.05 -> 14785.4 | N39: Retail | O39: New | P39: =IF(COUNTIF(B:B,B39)=1,"New Client","Old Client") -> Old Client | Q39: =IF(COUNTIFS($B:$B,$B39,$F:$F,"Liability")>0,"Yes","No") -> Yes | R39: =IF(AND($Q39="Yes",$F39<>"Liability"),"Cross-Sold","") -> Cross-Sold
A40: PL 557 | B40: 208 | C40: Offline | D40: Not POS | E40: Bajaj Allianz General Insurance Co Ltd | F40: =VLOOKUP(G40,'Policy Type'!$A:$B,2,FALSE) -> Others | G40: Travel | H40: 45182 | I40: 45228 | J40: 213800 | K40: =J40*0.18 -> 38484 | L40: =J40+K40 -> 252284 | M40: =L40*0.15 -> 37842.6 | N40: Retail | O40: New | P40: =IF(COUNTIF(B:B,B40)=1,"New Client","Old Client") -> New Client | Q40: =IF(COUNTIFS($B:$B,$B40,$F:$F,"Liability")>0,"Yes","No") -> No | R40: =IF(AND($Q40="Yes",$F40<>"Liability"),"Cross-Sold","")
...

Sheet Pivot Table 6
A1: SUM of Gross Premium | B1: Client Type
A2: Policy Name | B2: Corporate | C2: Retail | D2: (blank) | E2: Grand Total
A3: All Business Risk | B3: 5397100 | E3: 5397100
A4: Arogya Sanjeevani | C4: 4626700 | E4: 4626700
A5: Bharat Griha Raksha | C5: 952100 | E5: 952100
A6: Bharat Laghu Udyam Suraksha | B6: 140048100 | E6: 140048100
A7: Bharat Sookshma Udyam Suraksha | B7: 34109100 | C7: 9431400 | E7: 43540500
A8: Burglary | B8: 86099000 | C8: 704800 | E8: 86803800
A9: Business Suraksha | B9: 45800200 | C9: 1016900 | E9: 46817100
A10: Commercial Crime | B10: 159654000 | E10: 159654000
A11: Commercial General Liability | B11: 493984100 | E11: 493984100
A12: Commercial Package | B12: 128604000 | C12: 10079000 | E12: 138683000
A13: Compact insurance | B13: 982900 | E13: 982900
A14: Contractor All Risk | B14: 639839900 | C14: 13518900 | E14: 653358800
A15: Contractor's Plant and Machinery | B15: 26437700 | C15: 1149400 | E15: 27587100
A16: Cyber Crime | B16: 1191574400 | E16: 1191574400
A17: D & O | B17: 455232100 | E17: 455232100
A18: Directors and Officers | B18: 181465800 | E18: 181465800
A19: E & O | B19: 422704400 | C19: 26194500 | E19: 448898900
A20: Electronic Equipment Policy | B20: 81697800 | E20: 81697800
A21: Erection All Risk | B21: 244211700 | E21: 244211700
A22: Errors and Omisssions | B22: 327098500 | C22: 531100 | E22: 327629600
A23: Extra Care | C23: 16907000 | E23: 16907000
A24: Extra Care Plus | B24: 594900 | C24: 19082200 | E24: 19677100
A25: Family Medicare | C25: 86654700 | E25: 86654700
A26: Fidelity Guarantee | C26: 35400 | E26: 35400
A27: FinTech Policy | B27: 80240000 | E27: 80240000
A28: Global Personal Guard | C28: 26050300 | E28: 26050300
A29: Goods Carrying Commercial Vehicle | B29: 136750700 | C29: 190543800 | E29: 327294500
A30: Goods Carrying Commercial Vehicle - TP | B30: 25430400 | C30: 23760700 | E30: 49191100
A31: Group Mediclaim | B31: 3857246600 | C31: 27711200 | E31: 3884957800
A32: Group Personal Accident | B32: 328225900 | E32: 328225900
A33: Happy Family Floater | C33: 17335900 | E33: 17335900
A34: Health Absolute | B34: 2046300 | C34: 34306700 | E34: 36353000
A35: Health Guard | C35: 149209900 | E35: 149209900
A36: Health Supreme | C36: 30960700 | E36: 30960700
A37: Health Suraksha | B37: 863500 | C37: 119878800 | E37: 120742300
A38: Health Total | C38: 19653400 | E38: 19653400
A39: Home Insurance | B39: 4283300 | C39: 53373300 | E39: 57656600
A40: Hospital Cash | C40: 383500 | E40: 383500
...

Sheet Pivot Table 5
A1: POS Location | B1: SUM of Gross Premium
A2: Ahemdabad | B2: 820599782
A3: Indore | B3: 956218884
A4: Mumbai | B4: 1386657356
A5: Nagpur | B5: 740109090
A6: Not POS | B6: 13611591547
A7: (blank)
A8: Grand Total | B8: 17515176659

Sheet Pivot Table 4
A1: Policy MIS New | B1: SUM of Gross Premium
A2: Endorsement
A3: New | B3: 6179396439
A4: Renew | B4: 8538863038
A5: Rollover | B5: 2796917182
A6: Grand Total | B6: 17515176659

Sheet Pivot Table 3
A1: Client Type | B1: SUM of Gross Premium
A2: Corporate | B2: 15383664849
A3: Retail | B3: 2131511810
A4: (blank)
A5: Grand Total | B5: 17515176659

Sheet Pivot Table 2
A1: Insurer Name | B1: SUM of Gross Premium
A2: Aditya Birla Insurance Company | B2: 137648500
A3: Bajaj Allianz General Insurance Co Ltd | B3: 2175950094
A4: Care Health Ltd | B4: 373367100
A5: Cholamandalam MS General Insurance | B5: 197695200 | D5: =MAX(B3:B25) -> 0
A6: Future Generali India Insurance Co Ltd | B6: 1585461428
A7: Go Digit General Insurance Ltd | B7: 266294721
A8: HDFC Ergo General Insurance Co Ltd | B8: 3640304492
A9: ICICI Lombard General Insurance Co Ltd | B9: 1310493904
A10: Iffco tokio general insurance co ltd | B10: 203466212
A11: Kotak Mahindra General Insurance Co. Ltd. | B11: 21577890
A12: Liberty General Insurance | B12: 726169876
A13: Magma HDI General Insurance Co Ltd | B13: 51366000
A14: National Insurance Co Ltd | B14: 446985100
A15: New India Assurance company | B15: 1174382436
A16: Niva Bupa Health Insurance Company Ltd | B16: 61029800
A17: Raheja QBE General Insurance Co. Ltd. | B17: 4081600
... A24: United India Insurance Co Ltd | B24: 1328011660
A25: (blank)
D29: =IFERROR(__xludf.DUMMYFUNCTION("QUERY(A:B, ""select A, sum(B) group by A order by sum(B) desc limit 5"", 1)"),"Insurer Name") -> Insurer Name | E29: =IFERROR(__xludf.DUMMYFUNCTION("""COMPUTED_VALUE"""),"sum SUM of Gross Premium") -> sum SUM of Gross Premium
D30: =IFERROR(__xludf.DUMMYFUNCTION("""COMPUTED_VALUE"""),"HDFC Ergo General Insurance Co Ltd") -> HDFC Ergo General Insurance Co Ltd | E30: =IFERROR(__xludf.DUMMYFUNCTION("""COMPUTED_VALUE"""),3640304492) -> 3640304492
D31: =IFERROR(__xludf.DUMMYFUNCTION("""COMPUTED_VALUE"""),"Bajaj Allianz General Insurance Co Ltd") -> Bajaj Allianz General Insurance Co Ltd | E31: =IFERROR(__xludf.DUMMYFUNCTION("""COMPUTED_VALUE"""),2175950094) -> 2175950094
D32: =IFERROR(__xludf.DUMMYFUNCTION("""COMPUTED_VALUE"""),"Future Generali India Insurance Co Ltd") -> Future Generali India Insurance Co Ltd | E32: =IFERROR(__xludf.DUMMYFUNCTION("""COMPUTED_VALUE"""),1585461428) -> 1585461428
D33: =IFERROR(__xludf.DUMMYFUNCTION("""COMPUTED_VALUE"""),"United India Insurance Co Ltd") -> United India Insurance Co Ltd | E33: =IFERROR(__xludf.DUMMYFUNCTION("""COMPUTED_VALUE"""),1328011660) -> 1328011660
D34: =IFERROR(__xludf.DUMMYFUNCTION("""COMPUTED_VALUE"""),"ICICI Lombard General Insurance Co Ltd") -> ICICI Lombard General Insurance Co Ltd | E34: =IFERROR(__xludf.DUMMYFUNCTION("""COMPUTED_VALUE"""),1310493904) -> 1310493904

Sheet Appendix>>

Sheet Policy Type
A1: Policy | B1: Category
A2: Workmen Compensation | B2: Liability
A3: Burglary | B3: P&C
A4: Marine Open | B4: P&C
A5: Premium Personal Guard | B5: P&C
A6: Two Wheeler | B6: P&C
A7: D & O | B7: Liability
A8: Two wheeler - TP | B8: P&C
A9: Private Car | B9: P&C
A10: Two Wheeler - OD | B10: P&C
A11: Specific Marine | B11: P&C
A12: E & O | B12: Liability
... A75: Arogya Sanjeevani | B75: Liability

Sheet Dashboards
A1: POS Dashboard - BIMA KAVACH
A2: Sales Channel | B2: SUM of Gross Premium | C2: SUM of Gross Premium
A3: Ads | B3: 5067132494 | C3: 17515176659
A4: BD | B4: 4260590787
A5: Offline | B5: 4283868266
A6: POS | B6: 3903585112
A7: (blank)
A8: Grand Total | B8: 17515176659

Sheet Crossssss
A1: Policy Name | B1: GWP
A2: Burglary | B2: =SUMIFS('Raw Data'!$J:$J,'Raw Data'!$G:$G,A2,'Raw Data'!$R:$R,"Cross-Sold") -> 42770500
A3: Marine Open | B3: =SUMIFS('Raw Data'!$J:$J,'Raw Data'!$G:$G,A3,'Raw Data'!$R:$R,"Cross-Sold") -> 174568900 | D3: =MAX(B2:B4143) -> 1184589200
A4: D & O | B4: =SUMIFS('Raw Data'!$J:$J,'Raw Data'!$G:$G,A4,'Raw Data'!$R:$R,"Cross-Sold") -> 0
A5: Two Wheeler | B5: =SUMIFS('Raw Data'!$J:$J,'Raw Data'!$G:$G,A5,'Raw Data'!$R:$R,"Cross-Sold") -> 13740226 | D5: {=INDEX(A2:A100,MATCH(MAX(B2:B100),B2:B100,0))} -> Group Mediclaim
A6: Two Wheeler | B6: =SUMIFS('Raw Data'!$J:$J,'Raw Data'!$G:$G,A6,'Raw Data'!$R:$R,"Cross-Sold") -> 13740226
A7: Two Wheeler | B7: =SUMIFS('Raw Data'!$J:$J,'Raw Data'!$G:$G,A7,'Raw Data'!$R:$R,"Cross-Sold") -> 13740226
A8: Marine Open | B8: =SUMIFS('Raw Data'!$J:$J,'Raw Data'!$G:$G,A8,'Raw Data'!$R:$R,"Cross-Sold") -> 174568900
A9: Specific Marine | B9: =SUMIFS('Raw Data'!$J:$J,'Raw Data'!$G:$G,A9,'Raw Data'!$R:$R,"Cross-Sold") -> 29707200
A10: D & O | B10: =SUMIFS('Raw Data'!$J:$J,'Raw Data'!$G:$G,A10,'Raw Data'!$R:$R,"Cross-Sold") -> 0
A11: E & O | B11: =SUMIFS('Raw Data'!$J:$J,'Raw Data'!$G:$G,A11,'Raw Data'!$R:$R,"Cross-Sold") -> 0
A12: Star Package | B12: =SUMIFS('Raw Data'!$J:$J,'Raw Data'!$G:$G,A12,'Raw Data'!$R:$R,"Cross-Sold") -> 26771200
A13: Shopkeeper | B13: =SUMIFS('Raw Data'!$J:$J,'Raw Data'!$G:$G,A13,'Raw Data'!$R:$R,"Cross-Sold") -> 7391100
A14: Public Liability | B14: =SUMIFS('Raw Data'!$J:$J,'Raw Data'!$G:$G,A14,'Raw Data'!$R:$R,"Cross-Sold") -> 0
A15: Workmen Compensation | B15: =SUMIFS('Raw Data'!$J:$J,'Raw Data'!$G:$G,A15,'Raw Data'!$R:$R,"Cross-Sold") -> 0
A16: Bharat Sookshma Udyam Suraksha | B16: =SUMIFS('Raw Data'!$J:$J,'Raw Data'!$G:$G,A16,'Raw Data'!$R:$R,"Cross-Sold") -> 15227800
A17: D & O | B17: =SUMIFS('Raw Data'!$J:$J,'Raw Data'!$G:$G,A17,'Raw Data'!$R:$R,"Cross-Sold") -> 0
... A4143: Errors and Omisssions | B4143: =SUMIFS('Raw Data'!$J:$J,'Raw Data'!$G:$G,A4143,'Raw Data'!$R:$R,"Cross-Sold") -> 0
